import { Encrypter, AddAccountModel, AccountModel, AddAccountRepository } from './db-add-account-protocols'
import { DbAddAccount } from '../add-account/db-add-account'
interface SutTypes {
  sut: DbAddAccount
  encrypterStub: Encrypter
  addAccountRepositoryStub: AddAccountRepository
}

const makeEncrypter = (): Encrypter => {
  class EncrypterStub implements Encrypter {
    async encrypt (value: string): Promise<string> {
      return await new Promise(resolve => resolve('hashed_password'))
    }
  }
  return new EncrypterStub()
}

const makeAddAccountRepository = (): AddAccountRepository => {
  class AddAccountRepositoryStub implements AddAccountRepository {
    // infra layer will see domain layer by using the same models
    async add (accountData: AddAccountModel): Promise<AccountModel> {
      const fakeAccount = {
        id: 'valid_id',
        name: 'valid_name',
        email: 'valid_email',
        password: 'hashed_password'
      }
      return await new Promise(resolve => resolve(fakeAccount))
    }
  }

  return new AddAccountRepositoryStub()
}

const makeSut = (): SutTypes => {
  const encrypterStub = makeEncrypter()
  const addAccountRepositoryStub = makeAddAccountRepository()
  const sut = new DbAddAccount(encrypterStub, addAccountRepositoryStub)
  return {
    sut,
    encrypterStub,
    addAccountRepositoryStub
  }
}

describe('DbAddAccount UseCase', () => {
  test('Should call encrypter with correct password', async () => {
    const { sut, encrypterStub } = makeSut()
    const encryptSpy = jest.spyOn(encrypterStub, 'encrypt')
    const accountData = {
      name: 'valid_name',
      email: 'valid_email',
      password: 'valid_password'
    }
    await sut.add(accountData)

    expect(encryptSpy).toHaveBeenCalledWith(accountData.password)
  })

  // checks that there's no try/catch block within the db-add-account implementation
  test('Should throw if encrypter throws', async () => {
    const { sut, encrypterStub } = makeSut()

    // we're forcing our dependency to return an exception
    jest.spyOn(encrypterStub, 'encrypt').mockReturnValueOnce(new Promise((resolve, reject) => reject(new Error())))
    const accountData = {
      name: 'valid_name',
      email: 'valid_email',
      password: 'valid_password'
    }
    const promise = sut.add(accountData)

    // we expect the exception to be thrown as a rejection call within the promise
    await expect(promise).rejects.toThrow()
  })

  test('Should call AddAccountRepository with correct values', async () => {
    const { sut, addAccountRepositoryStub } = makeSut()
    const addSpy = jest.spyOn(addAccountRepositoryStub, 'add')
    const accountData = {
      name: 'valid_name',
      email: 'valid_email',
      password: 'valid_password'
    }
    await sut.add(accountData)

    expect(addSpy).toHaveBeenCalledWith({
      name: 'valid_name',
      email: 'valid_email',
      password: 'hashed_password'
    })
  })

  test('Should throw if AddAccountRepository throws', async () => {
    const { sut, addAccountRepositoryStub } = makeSut()

    // we're forcing our dependency to return an exception
    jest.spyOn(addAccountRepositoryStub, 'add').mockReturnValueOnce(new Promise((resolve, reject) => reject(new Error())))
    const accountData = {
      name: 'valid_name',
      email: 'valid_email',
      password: 'valid_password'
    }
    const promise = sut.add(accountData)

    // we expect the exception to be thrown as a rejection call within the promise
    await expect(promise).rejects.toThrow()
  })
})
